<?xml version="1.0"?>
<robot xmlns:xacro="http://www.ros.org/wiki/xacro" name="navy">
        <xacro:include filename="$(find robot_description)/urdf/plugins.gazebo"/>
    <link name="base_link">
       <inertial>
        <origin xyz="0.0 0.0 0.0" rpy="0.0 0.0 0.0"/>
        <mass value="1"/>
        <inertia ixx="0.0257" ixy="0.0" ixz="0.0" 
             iyy="0.0680" iyz="0.0" 
             izz="0.0927"/>
        </inertial>
        <visual name="body_visual">
            <origin xyz="0.0 0.0 0.0" rpy="0.0 0.0 0.0"/>
            <geometry>
                <box size="0.4 0.25 0.05"/>
            </geometry>
            <material name="white">
                <color rgba="1.0 1.0 1.0 1.0"/>
                <texture filename=""/>
            </material>
        </visual>
        <collision>
            <geometry>
                <box size="0.4 0.25 0.08"/>
            </geometry>
        </collision>
    </link>

    <link name="BLW_link">
        <inertial>
            <origin xyz="0.0 0.0 0.0" rpy="0 0 0"/>
            <mass value="0.5"/>
<inertia ixx="0.00531" ixy="0.0" ixz="0.0" iyy="0.00531" iyz="0.0" izz="0.005625"/>
        </inertial>
        <visual name="">
            <origin xyz="0 0 0.0" rpy="0 1.570796327 1.570796327"/>
            <geometry>
            <cylinder radius="0.05" length="0.04"/>      
                  </geometry>
            <material name="">
                <color rgba="0.0 0.0 0.0 1.0"/>
                <texture filename=""/>
            </material>
        </visual>
        <collision>
            <origin xyz="0.0 0.0 0.0" rpy="0 1.570796327 1.570796327"/>
            <geometry>
            <cylinder radius="0.05" length="0.04"/>      
            </geometry>
        </collision>
    </link>
    <joint name="BLW_joint" type="continuous">
            <origin xyz="-0.14 0.15 -0.02" rpy="0 0 0"/>
        <parent link="base_link"/>
        <child link="BLW_link"/>
        <axis xyz="0 1 0"/>
          <!-- <dynamics damping="0.1" friction="0.01"/> -->
        </joint>
        <link name="BRW_link">
        <inertial>
            <origin xyz="0.0 0.0 0.0" rpy="0.0 0.0 0.0"/>
            <mass value="0.5"/>
<inertia ixx="0.00531" ixy="0.0" ixz="0.0" iyy="0.00531" iyz="0.0" izz="0.005625"/>
        </inertial>
        <visual name="">
            <origin xyz="0 0 0.0" rpy="0 1.570796327 1.570796327"/>
            <geometry>
            <cylinder radius="0.05" length="0.04"/>      
                  </geometry>
            <material name="">
                <color rgba="0.0 0.0 0.0 1.0"/>
                <texture filename=""/>
            </material>
        </visual>
        <collision>
            <origin xyz="0.0 0.0 0.0" rpy="0 1.570796327 1.570796327"/>
            <geometry>
            <cylinder radius="0.05" length="0.04"/>      
            </geometry>
        </collision>
    </link>
    <joint name="BRW_joint" type="continuous">
            <origin xyz="-0.14 -0.15 -0.02" rpy="0 0 0"/>
        <parent link="base_link"/>
        <child link="BRW_link"/>
        <axis xyz="0 1 0"/>
          <!-- <dynamics damping="0.1" friction="0.01"/> -->
        </joint>
        <link name="FLW_link">
        <inertial>
            <origin xyz="0.0 0.0 0.0" rpy="0.0 0.0 0.0"/>
            <mass value="0.5"/>
<inertia ixx="0.00531" ixy="0.0" ixz="0.0" iyy="0.00531" iyz="0.0" izz="0.005625"/>
        </inertial>
        <visual name="">
            <origin xyz="0 0 0.0" rpy="0 1.570796327 1.570796327"/>
            <geometry>
            <cylinder radius="0.05" length="0.04"/>      
                  </geometry>
            <material name="">
                <color rgba="0.0 0.0 0.0 1.0"/>
                <texture filename=""/>
            </material>
        </visual>
        <collision>
            <origin xyz="0.0 0.0 0.0" rpy="0 1.570796327 1.570796327"/>
            <geometry>
            <cylinder radius="0.05" length="0.04"/>      
            </geometry>
        </collision>
    </link>
    <joint name="FLW_joint" type="continuous">
            <origin xyz="0.14 0.15 -0.02" rpy="0 0 0  "/>
        <parent link="base_link"/>
        <child link="FLW_link"/>
        <axis xyz="0 1 0"/>
          <!-- <dynamics damping="0.1" friction="0.01"/> -->
     </joint>
        <link name="FRW_link">
        <inertial>
            <origin xyz="0.0 0.0 0.0" rpy="0.0 0.0 0.0"/>
            <mass value="0.5"/>
<inertia ixx="0.00531" ixy="0.0" ixz="0.0" iyy="0.00531" iyz="0.0" izz="0.005625"/>
        </inertial>
        <visual name="">
            <origin xyz="0 0 0.0" rpy="0 1.570796327 1.570796327"/>
            <geometry>
            <cylinder radius="0.05" length="0.04"/>      
                  </geometry>
            <material name="">
                <color rgba="0.0 0.0 0.0 1.0"/>
                <texture filename=""/>
            </material>
        </visual>
        <collision>
            <origin xyz="0.0 0.0 0.0" rpy="0 1.570796327 1.570796327"/>
            <geometry>
            <cylinder radius="0.05" length="0.04"/>      
            </geometry>
        </collision>
    </link>
    <joint name="FRW_joint" type="continuous">
            <origin xyz="0.14 -0.15 -0.02" rpy="0 0 0"/>
        <parent link="base_link"/>
        <child link="FRW_link"/>
        <axis xyz="0 1 0"/>
          <!-- <dynamics damping="0.1" friction="0.2"/> -->
        </joint>

    <link name="spacer_BL">
        <inertial>
            <origin xyz="0.0 0.0 0.0" rpy="0.0 0.0 0.0"/>
            <mass value="0.04"/>
            <inertia ixx="0.1" ixy="0.0" ixz="0.0" iyy="0.1" iyz="0.0" izz="0.1"/>
        </inertial>
        <visual name="">
            <origin xyz="-0 0 0" rpy="0.0 0.0 0.0"/>
            <geometry>
            <cylinder radius="0.004" length="0.08"/>        
                </geometry>
            <material name="">
                <color rgba="0.0 0.0 0.0 1.0"/>
                <texture filename=""/>
            </material>
        </visual>
        <collision>
            <origin xyz="0.0 0.0 0.0" rpy="0.0 0.0 0.0"/>
            <geometry>
            <cylinder radius="0.004" length="0.08"/>        
            </geometry>
        </collision>
    </link>
    <joint name="spacer_BL_joint" type="fixed">
        <origin xyz="-0.17 0.1 0.06" rpy="0.0 0.0 0.0"/>
        <parent link="base_link"/>
        <child link="spacer_BL"/>
    </joint>
    <link name="spacer_BR">
        <inertial>
            <origin xyz="0.0 0.0 0.0" rpy="0.0 0.0 0.0"/>
            <mass value="0.04"/>
            <inertia ixx="0.1" ixy="0.0" ixz="0.0" iyy="0.1" iyz="0.0" izz="0.1"/>
        </inertial>
        <visual name="">
            <origin xyz="-0 0 0" rpy="0.0 0.0 0.0"/>
            <geometry>
            <cylinder radius="0.004" length="0.08"/>        
                </geometry>
            <material name="">
                <color rgba="0.0 0.0 0.0 1.0"/>
                <texture filename=""/>
            </material>
        </visual>
        <collision>
            <origin xyz="0.0 0.0 0.0" rpy="0.0 0.0 0.0"/>
            <geometry>
            <cylinder radius="0.004" length="0.08"/>        
            </geometry>
        </collision>
    </link>
    <joint name="spacer_BR_joint" type="fixed">
        <origin xyz="-0.17 -0.1 0.06" rpy="0.0 0.0 0.0"/>
        <parent link="base_link"/>
        <child link="spacer_BR"/>
    </joint>
    <link name="spacer_FL">
        <inertial>
            <origin xyz="0.0 0.0 0.0" rpy="0.0 0.0 0.0"/>
            <mass value="0.04"/>
            <inertia ixx="0.1" ixy="0.0" ixz="0.0" iyy="0.1" iyz="0.0" izz="0.1"/>
        </inertial>
        <visual name="">
            <origin xyz="-0 0 0" rpy="0.0 0.0 0.0"/>
            <geometry>
            <cylinder radius="0.004" length="0.08"/>        
                </geometry>
            <material name="">
                <color rgba="0.0 0.0 0.0 1.0"/>
                <texture filename=""/>
            </material>
        </visual>
        <collision>
            <origin xyz="0.0 0.0 0.0" rpy="0.0 0.0 0.0"/>
            <geometry>
            <cylinder radius="0.004" length="0.08"/>        
            </geometry>
        </collision>
    </link>
    <joint name="spacer_FL_joint" type="fixed">
        <origin xyz="0.17 0.1 0.06" rpy="0.0 0.0 0.0"/>
        <parent link="base_link"/>
        <child link="spacer_FL"/>
    </joint>
    <link name="spacer_FR">
        <inertial>
            <origin xyz="0.0 0.0 0.0" rpy="0.0 0.0 0.0"/>
            <mass value="0.04"/>
            <inertia ixx="0.1" ixy="0.0" ixz="0.0" iyy="0.1" iyz="0.0" izz="0.1"/>
        </inertial>
        <visual name="">
            <origin xyz="-0 0 0" rpy="0.0 0.0 0.0"/>
            <geometry>
            <cylinder radius="0.004" length="0.08"/>        
                </geometry>
            <material name="">
                <color rgba="0.0 0.0 0.0 1.0"/>
                <texture filename=""/>
            </material>
        </visual>
        <collision>
            <origin xyz="0.0 0.0 0.0" rpy="0.0 0.0 0.0"/>
            <geometry>
            <cylinder radius="0.004" length="0.08"/>        
            </geometry>
        </collision>
    </link>
    <joint name="spacer_FR_joint" type="fixed">
        <origin xyz="0.17 -0.1 0.06" rpy="0.0 0.0 0.0"/>
        <parent link="base_link"/>
        <child link="spacer_FR"/>
    </joint>

    <link name="top_link">
        <inertial>
            <origin xyz="0.0 0.0 0.0" rpy="0.0 0.0 0.0"/>
            <mass value="1"/>
        <inertia ixx="0.0257" ixy="0.0" ixz="0.0" 
             iyy="0.0680" iyz="0.0" 
             izz="0.0927"/>        </inertial>
        <visual name="">
            <origin xyz="0.0 0.0 0" rpy="0.0 0.0 0.0"/>
            <geometry>
                <box size="0.4 0.25 0.05"/>
            </geometry>
            <material name="">
                <color rgba="1.0 1.0 1.0 1.0"/>
                <texture filename=""/>
            </material>
        </visual>
        <collision>
            <origin xyz="0.0 0.0 0.0" rpy="0.0 0.0 0.0"/>
            <geometry>
                <box size="0.4 0.25 0.05"/>
            </geometry>
        </collision>
    </link>
    <joint name="top_joint" type="fixed">
        <origin xyz="0.0 0.0 0.1" rpy="0.0 0.0 0.0"/>
        <parent link="base_link"/>
        <child link="top_link"/>
    </joint>

    <link name="lidar_link">
        <inertial>
            <origin xyz="0.0 0.0 0.0" rpy="0.0 0.0 0.0"/>
            <mass value="0.01"/>
            <inertia ixx="1e-6" ixy="0.0" ixz="0.0" iyy="1e-6" iyz="0.0" izz="1e-6" />    
        </inertial>
        <visual name="">
            <origin xyz="0.0 0.0 0.0" rpy="0.0 0.0 0.0"/>
            <geometry>
            <mesh filename="package://robot_description/meshes/rplidar-a2.stl" />
                  </geometry>
            <material name="">
                <color rgba="0.0 0.0 0.0 1.0"/>
                <texture filename=""/>
            </material>
        </visual>
        <collision>
            <origin xyz="0.0 0.0 0.0" rpy="0.0 0.0 0.0"/>
            <geometry>
            <mesh filename="package://robot_description/meshes/rplidar-a2.stl" />
            </geometry>
        </collision>
    </link>
    <joint name="lidar_joint" type="fixed">
        <origin xyz="0.12 0.0 0.18" rpy="0.0 0.0 0.0"/>
        <parent link="base_link"/>
        <child link="lidar_link"/>
    </joint>

   
    <link name="ultrasonicF_link">
        <inertial>
            <origin xyz="0.0 0.0 0.0" rpy="0.0 0.0 0.0"/>
            <mass value="0.0"/>
            <inertia ixx="0.0" ixy="0.0" ixz="0.0" iyy="0.0" iyz="0.0" izz="0.0"/>
        </inertial>
        <visual name="">
            <origin xyz="0 0 0" rpy="0.0 0.0 0.0"/>
            <geometry>
                <box size="0.01 0.08 0.02"/>
            </geometry>
            <material name="">
                <color rgba="1.0 0.0 0.0 1.0"/>
                <texture filename=""/>
            </material>
        </visual>
        <collision>
            <origin xyz="0.0 0.0 0.0" rpy="0.0 0.0 0.0"/>
            <geometry>
                <box size="0.01 0.08 0.02"/>
            </geometry>
        </collision>
    </link>
    <joint name="ultrasonicF_joint" type="fixed">
        <origin xyz="0.2 0.0 0.01" rpy="0.0 0.0 0.0"/>
        <parent link="base_link"/>
        <child link="ultrasonicF_link"/>
    </joint>
       <link name="ultrasonicB_link">
        <inertial>
            <origin xyz="0.0 0.0 0.0" rpy="0.0 0.0 0.0"/>
            <mass value="0.0"/>
            <inertia ixx="0.0" ixy="0.0" ixz="0.0" iyy="0.0" iyz="0.0" izz="0.0"/>
        </inertial>
        <visual name="">
            <origin xyz="0 0 0" rpy="0.0 0.0 0.0"/>
            <geometry>
                <box size="0.01 0.08 0.02"/>
            </geometry>
            <material name="">
                <color rgba="1.0 0.0 0.0 1.0"/>
                <texture filename=""/>
            </material>
        </visual>
        <collision>
            <origin xyz="0.0 0.0 0.0" rpy="0.0 0.0 0.0"/>
            <geometry>
                <box size="0.01 0.08 0.02"/>
            </geometry>
        </collision>
    </link>
    <joint name="ultrasonicB_joint" type="fixed">
        <origin xyz="-0.2 0.0 0.01" rpy="0.0 0.0 0.0"/>
        <parent link="base_link"/>
        <child link="ultrasonicB_link"/>
    </joint>
    
    <link name="depthcamera">
     <inertial>
            <origin xyz="0.0 0.0 0.0" rpy="0.0 0.0 0.0"/>
            <mass value="0.0"/>
            <inertia ixx="0.0" ixy="0.0" ixz="0.0" iyy="0.0" iyz="0.0" izz="0.0"/>
        </inertial>
        <visual name="">
            <origin xyz="0 0 0" rpy="0.0 0.0 0.0"/>
            <geometry>
                <box size="0.01 0.1 0.02"/>
            </geometry>
            <material name="">
                <color rgba="0.0 0.0 0.0 1.0"/>
                <texture filename=""/>
            </material>
        </visual>
        <collision>
            <origin xyz="0.0 0.0 0.0" rpy="0.0 0.0 0.0"/>
            <geometry>
                <box size="0.01 0.1 0.02"/>
            </geometry>
        </collision>
    </link>

      <joint name="depthcamera_joint" type="fixed">
        <origin xyz="0.2 0.0 0.1" rpy="0.0 0.0 0.0"/>
        <parent link="base_link"/>
        <child link="depthcamera"/>
    </joint>

</robot>
